<?xml version='1.0' encoding='utf-8'?>
<mujoco model="Humanoid">
  <option timestep="0.005" />

  <visual>
    <map force="0.1" zfar="30" />
    <rgba haze="0.15 0.25 0.35 1" />
    <global offwidth="2560" offheight="1440" elevation="-20" azimuth="120" />
  </visual>

  <statistic center="0 0 0.7" />

  <asset>
    <texture type="skybox" builtin="gradient" rgb1=".3 .5 .7" rgb2="0 0 0" width="32" height="512" />
    <texture name="body" type="cube" builtin="flat" mark="cross" width="128" height="128" rgb1="0.8 0.6 0.4" rgb2="0.8 0.6 0.4" markrgb="1 1 1" />
    <material name="body" texture="body" texuniform="true" rgba="0.8 0.6 .4 1" />
    <texture name="grid" type="2d" builtin="checker" width="512" height="512" rgb1=".1 .2 .3" rgb2=".2 .3 .4" />
    <material name="grid" texture="grid" texrepeat="1 1" texuniform="true" reflectance=".2" />
  </asset>

  <default>
    <motor ctrlrange="-1 1" ctrllimited="true" />
    <default class="body">

      
      <geom type="capsule" condim="1" friction=".7" solimp=".9 .99 .003" solref=".015 1" material="body" group="1" />
      <default class="thigh">
        <geom size=".06" />
      </default>
      <default class="shin">
        <geom fromto="0 0 0 0 0 -.3" size=".049" />
      </default>
      <default class="foot">
        <geom size=".027" />
        <default class="foot1">
          <geom fromto="-.07 -.01 0 .14 -.03 0" />
        </default>
        <default class="foot2">
          <geom fromto="-.07 .01 0 .14  .03 0" />
        </default>
      </default>
      <default class="arm_upper">
        <geom size=".04" />
      </default>
      <default class="arm_lower">
        <geom size=".031" />
      </default>
      <default class="hand">
        <geom type="sphere" size=".04" />
      </default>

      
      <joint type="hinge" damping=".2" stiffness="1" armature=".01" limited="true" solimplimit="0 .99 .01" />
      <default class="joint_big">
        <joint damping="5" stiffness="10" />
        <default class="hip_x">
          <joint range="-30 10" />
        </default>
        <default class="hip_z">
          <joint range="-60 35" />
        </default>
        <default class="hip_y">
          <joint axis="0 1 0" range="-150 20" />
        </default>
        <default class="joint_big_stiff">
          <joint stiffness="20" />
        </default>
      </default>
      <default class="knee">
        <joint pos="0 0 .02" axis="0 -1 0" range="-160 2" />
      </default>
      <default class="ankle">
        <joint range="-50 50" />
        <default class="ankle_y">
          <joint pos="0 0 .08" axis="0 1 0" stiffness="6" />
        </default>
        <default class="ankle_x">
          <joint pos="0 0 .04" stiffness="3" />
        </default>
      </default>
      <default class="shoulder">
        <joint range="-85 60" />
      </default>
      <default class="elbow">
        <joint range="-100 50" stiffness="0" />
      </default>
    </default>
  </default>

  <worldbody>
    <geom name="floor" size="0 0 .05" type="plane" material="grid" condim="3" />
    <light name="spotlight" mode="targetbodycom" target="torso" diffuse=".8 .8 .8" specular="0.3 0.3 0.3" pos="0 -6 4" cutoff="30" />
    <light name="top" pos="0 0 2" mode="trackcom" />
    <body name="torso" pos="0 0 1.282" childclass="body">
      <camera name="back" pos="-3 0 1" xyaxes="0 -1 0 1 0 2" mode="trackcom" />
      <camera name="side" pos="0 -3 1" xyaxes="1 0 0 0 1 2" mode="trackcom" />
      <freejoint name="root" />
      <geom name="torso" fromto="0 -.07 0 0 .07 0" size=".07" />
      <geom name="waist_upper" fromto="-.01 -.06 -.12 -.01 .06 -.12" size=".06" />
      <body name="head" pos="0 0 .19">
        <geom name="head" type="sphere" size=".09" />
        <camera name="egocentric" pos=".09 0 0" xyaxes="0 -1 0 .1 0 1" fovy="80" />
      </body>
      <body name="waist_lower" pos="-.01 0 -.26">
        <geom name="waist_lower" fromto="0 -.06 0 0 .06 0" size=".06" />
        <joint name="abdomen_z" pos="0 0 .065" axis="0 0 1" range="-45 45" class="joint_big_stiff" />
        <joint name="abdomen_y" pos="0 0 .065" axis="0 1 0" range="-75 30" class="joint_big" />
        <body name="pelvis" pos="0 0 -.165">
          <joint name="abdomen_x" pos="0 0 .1" axis="1 0 0" range="-35 35" class="joint_big" />
          <geom name="butt" fromto="-.02 -.07 0 -.02 .07 0" size=".09" />
          <body name="thigh_right" pos="0 -.1 -.04">
            <joint name="hip_x_right" axis="1 0 0" class="hip_x" />
            <joint name="hip_z_right" axis="0 0 1" class="hip_z" />
            <joint name="hip_y_right" class="hip_y" />
            <geom name="thigh_right" fromto="0 0 0 0 .01 -.34" class="thigh" />
            <body name="shin_right" pos="0 .01 -.4">
              <joint name="knee_right" class="knee" />
              <geom name="shin_right" class="shin" />
              <body name="foot_right" pos="0 0 -.39">
                <joint name="ankle_y_right" class="ankle_y" />
                <joint name="ankle_x_right" class="ankle_x" axis="1 0 .5" />
                <geom name="foot1_right" class="foot1" />
                <geom name="foot2_right" class="foot2" />
              </body>
            </body>
          </body>
          <body name="thigh_left" pos="0 .1 -.04">
            <joint name="hip_x_left" axis="-1 0 0" class="hip_x" />
            <joint name="hip_z_left" axis="0 0 -1" class="hip_z" />
            <joint name="hip_y_left" class="hip_y" />
            <geom name="thigh_left" fromto="0 0 0 0 -.01 -.34" class="thigh" />
            <body name="shin_left" pos="0 -.01 -.4">
              <joint name="knee_left" class="knee" />
              <geom name="shin_left" fromto="0 0 0 0 0 -.3" class="shin" />
              <body name="foot_left" pos="0 0 -.39">
                <joint name="ankle_y_left" class="ankle_y" />
                <joint name="ankle_x_left" class="ankle_x" axis="-1 0 -.5" />
                <geom name="foot1_left" class="foot1" />
                <geom name="foot2_left" class="foot2" />
              </body>
            </body>
          </body>
        </body>
      </body>
      <body name="upper_arm_right" pos="0 -.17 .06">
        <joint name="shoulder1_right" axis="2 1 1" class="shoulder" />
        <joint name="shoulder2_right" axis="0 -1 1" class="shoulder" />
        <geom name="upper_arm_right" fromto="0 0 0 .16 -.16 -.16" class="arm_upper" />
        <body name="lower_arm_right" pos=".18 -.18 -.18">
          <joint name="elbow_right" axis="0 -1 1" class="elbow" />
          <geom name="lower_arm_right" fromto=".01 .01 .01 .17 .17 .17" class="arm_lower" />
          <body name="hand_right" pos=".18 .18 .18">
            <geom name="hand_right" zaxis="1 1 1" class="hand" />
          </body>
        </body>
      </body>
      <body name="upper_arm_left" pos="0 .17 .06">
        <joint name="shoulder1_left" axis="-2 1 -1" class="shoulder" />
        <joint name="shoulder2_left" axis="0 -1 -1" class="shoulder" />
        <geom name="upper_arm_left" fromto="0 0 0 .16 .16 -.16" class="arm_upper" />
        <body name="lower_arm_left" pos=".18 .18 -.18">
          <joint name="elbow_left" axis="0 -1 -1" class="elbow" />
          <geom name="lower_arm_left" fromto=".01 -.01 .01 .17 -.17 .17" class="arm_lower" />
          <body name="hand_left" pos=".18 -.18 .18">
            <geom name="hand_left" zaxis="1 -1 1" class="hand" />
          </body>
        </body>
      </body>
    </body>
  </worldbody>

  <contact>
    <exclude body1="waist_lower" body2="thigh_right" />
    <exclude body1="waist_lower" body2="thigh_left" />
  </contact>

  <tendon>
    <fixed name="hamstring_right" limited="true" range="-0.3 2">
      <joint joint="hip_y_right" coef=".5" />
      <joint joint="knee_right" coef="-.5" />
    </fixed>
    <fixed name="hamstring_left" limited="true" range="-0.3 2">
      <joint joint="hip_y_left" coef=".5" />
      <joint joint="knee_left" coef="-.5" />
    </fixed>
  </tendon>

  <actuator>
    <motor name="abdomen_z" gear="40" joint="abdomen_z" />
    <motor name="abdomen_y" gear="40" joint="abdomen_y" />
    <motor name="abdomen_x" gear="40" joint="abdomen_x" />
    <motor name="hip_x_right" gear="40" joint="hip_x_right" />
    <motor name="hip_z_right" gear="40" joint="hip_z_right" />
    <motor name="hip_y_right" gear="120" joint="hip_y_right" />
    <motor name="knee_right" gear="80" joint="knee_right" />
    <motor name="ankle_y_right" gear="20" joint="ankle_y_right" />
    <motor name="ankle_x_right" gear="20" joint="ankle_x_right" />
    <motor name="hip_x_left" gear="40" joint="hip_x_left" />
    <motor name="hip_z_left" gear="40" joint="hip_z_left" />
    <motor name="hip_y_left" gear="120" joint="hip_y_left" />
    <motor name="knee_left" gear="80" joint="knee_left" />
    <motor name="ankle_y_left" gear="20" joint="ankle_y_left" />
    <motor name="ankle_x_left" gear="20" joint="ankle_x_left" />
    <motor name="shoulder1_right" gear="20" joint="shoulder1_right" />
    <motor name="shoulder2_right" gear="20" joint="shoulder2_right" />
    <motor name="elbow_right" gear="40" joint="elbow_right" />
    <motor name="shoulder1_left" gear="20" joint="shoulder1_left" />
    <motor name="shoulder2_left" gear="20" joint="shoulder2_left" />
    <motor name="elbow_left" gear="40" joint="elbow_left" />
  </actuator>

  <keyframe>
    
    <key name="squat" qpos="0 0 0.596                0.988015 0 0.154359 0                0 0.4 0                -0.25 -0.5 -2.5 -2.65 -0.8 0.56                -0.25 -0.5 -2.5 -2.65 -0.8 0.56                0 0 0 0 0 0" />
    <key name="stand_on_left_leg" qpos="0 0 1.21948                0.971588 -0.179973 0.135318 -0.0729076                -0.0516 -0.202 0.23                -0.24 -0.007 -0.34 -1.76 -0.466 -0.0415                -0.08 -0.01 -0.37 -0.685 -0.35 -0.09                0.109 -0.067 -0.7 -0.05 0.12 0.16" />
    <key name="prone" qpos="0.4 0 0.0757706                0.7325 0 0.680767 0                0 0.0729 0                0.0077 0.0019 -0.026 -0.351 -0.27 0                0.0077 0.0019 -0.026 -0.351 -0.27 0                0.56 -0.62 -1.752                0.56 -0.62 -1.752" />
    <key name="supine" qpos="-0.4 0 0.08122                0.722788 0 -0.69107 0                0 -0.25 0                0.0182 0.0142 0.3 0.042 -0.44 -0.02                0.0182 0.0142 0.3 0.042 -0.44 -0.02                0.186 -0.73 -1.73                0.186 -0.73 -1.73" />
  <key name="initial_pose" time="0.000" qpos="-0.000515 0.004641 1.281256 1.000000 0.000062 0.000029 0.000030 0.006075 -0.001573 0.002672 0.005126 0.001534 0.009769 0.009276 -0.003075 0.006233 -0.003197 -0.000128 0.008169 0.000684 0.004005 -0.001210 -0.001274 0.007178 -0.005535 -0.006552 -0.006098 -0.007451" qvel="0.010562 0.004954 -0.013780 0.024710 0.011620 0.011907 0.014493 -0.037925 -0.205504 0.219176 0.081004 0.015842 -0.009727 0.090115 -0.345803 -0.201373 -0.014268 0.016863 -0.190156 -0.697857 0.095963 0.025717 -0.041757 0.006232 0.103555 -0.042155 -0.016101" /><key time="0.000" qpos="-0.000515 0.004641 1.281256 1.000000 0.000062 0.000029 0.000030 0.006075 -0.001573 0.002672 0.005126 0.001534 0.009769 0.009276 -0.003075 0.006233 -0.003197 -0.000128 0.008169 0.000684 0.004005 -0.001210 -0.001274 0.007178 -0.005535 -0.006552 -0.006098 -0.007451" qvel="0.010562 0.004954 -0.013780 0.024710 0.011620 0.011907 0.014493 -0.037925 -0.205504 0.219176 0.081004 0.015842 -0.009727 0.090115 -0.345803 -0.201373 -0.014268 0.016863 -0.190156 -0.697857 0.095963 0.025717 -0.041757 0.006232 0.103555 -0.042155 -0.016101" /><key time="0.025" qpos="0.068831 -0.002060 1.252880 0.996050 0.005415 0.006188 -0.088412 0.190689 0.448974 -0.003828 0.068141 -0.127561 -0.541516 -0.023514 0.050810 0.014590 0.012330 -0.046729 -0.511019 0.042096 0.084680 0.228194 0.336170 -0.190426 0.962955 -0.051998 -0.780538 0.914323" qvel="0.294370 0.017006 -0.201163 0.376531 -0.323506 -0.041905 0.957394 2.491881 -0.569657 1.153419 -0.924313 1.117542 7.419730 4.359402 -1.031782 -0.383985 0.668661 -2.363497 -0.029049 -0.176716 -0.357929 3.140294 -4.107546 -2.662649 5.713992 -4.855012 -1.312830" /><key time="0.050" qpos="0.064163 0.002183 1.256755 0.994998 -0.014767 0.024528 -0.095708 0.208627 0.329016 -0.013549 0.119730 -0.101065 -0.403700 0.043660 0.063005 0.028492 -0.062931 -0.001169 -0.575109 -0.277651 -0.081996 0.026335 0.696452 -0.347948 0.745387 0.316791 -0.718531 0.809424" qvel="-0.300819 -0.029387 0.065929 0.175815 -1.188563 -0.244718 -1.194683 -0.274780 -0.786371 -0.071124 1.671355 1.924696 -0.023096 -0.161353 1.243945 -0.108256 -2.223032 0.636761 -2.715465 -0.462043 0.871501 0.874363 1.658890 -1.977421 0.493852 2.242360 -3.926656" /><key time="0.075" qpos="0.043596 -0.000367 1.261712 0.989902 -0.020518 -0.013140 -0.139647 0.251592 0.281937 -0.040759 0.141427 -0.005756 -0.250395 0.043554 0.030940 -0.064016 -0.100208 -0.068283 -0.499420 -0.454042 -0.213710 0.036264 0.992396 -0.087468 0.799075 0.325644 -0.474851 0.558996" qvel="-0.062517 -0.035719 -0.055798 -0.018253 -0.636432 -1.065183 -0.551916 0.467951 -0.462007 0.261223 1.696226 0.188158 -0.056106 0.042784 -0.501876 -0.403328 -0.772361 -0.240672 -1.790626 -1.350607 -1.763692 2.279813 2.863399 1.837513 0.601347 1.095893 -1.064491" /><key time="0.100" qpos="0.039841 -0.001354 1.258536 0.984738 -0.016432 -0.023110 -0.171716 0.256078 0.263090 -0.101720 0.181677 0.053756 -0.200167 0.043193 0.023852 -0.058918 -0.148660 -0.127281 -0.491900 -0.571841 -0.296793 0.044448 0.996807 0.145628 0.881149 0.403623 -0.291807 0.402315" qvel="0.002212 -0.033201 0.072549 0.119281 0.183554 -0.764204 0.619176 -0.871804 -0.013562 -0.243223 0.100802 0.967642 0.029298 -0.254804 0.266818 0.148947 -0.106811 1.242495 0.484697 -0.083371 0.049090 -1.197573 0.827464 -0.012717 0.466942 0.122018 -1.071533" /><key time="0.125" qpos="0.052884 -0.005395 1.255174 0.982196 -0.009048 -0.017581 -0.186814 0.299448 0.297607 -0.118228 0.181374 0.044646 -0.242927 0.042243 0.019338 -0.060829 -0.136381 -0.135583 -0.567214 -0.614797 -0.284822 0.038544 1.029176 0.172790 0.853880 0.397969 -0.210197 0.373291" qvel="0.170024 -0.021486 -0.084858 -0.024096 -0.344570 -0.617450 0.021452 1.455799 -0.061023 -0.010480 0.675920 -1.312306 -0.105009 0.161852 0.016471 -0.245416 0.048797 -1.325235 -0.378605 -0.013823 0.144451 0.930831 -1.381550 -1.807259 0.073656 -0.499907 0.692110" /><key time="0.150" qpos="0.073699 -0.003034 1.251220 0.982281 -0.014565 -0.001635 -0.186842 0.276040 0.297803 -0.120759 0.181263 0.070606 -0.268559 0.044162 0.011440 -0.064982 -0.146700 -0.130511 -0.577421 -0.598955 -0.316066 0.026641 1.003469 -0.024731 0.862638 0.534616 -0.155737 0.512087" qvel="0.121222 0.041216 -0.034525 -0.393023 1.094779 -0.081603 0.451335 -1.676388 -0.133450 0.412183 -0.307438 0.641634 0.055846 -0.240371 -0.210497 -0.445939 0.331543 0.067055 -0.952547 -0.504171 -0.005640 -0.653007 -0.623904 -1.046884 0.663079 1.007537 0.679122" /><key time="0.175" qpos="0.094163 -0.002309 1.244574 0.977520 -0.020238 0.007350 -0.209740 0.295061 0.344790 -0.125539 0.182057 0.087754 -0.337909 0.044228 0.020346 -0.031874 -0.161024 -0.130892 -0.653988 -0.631163 -0.319607 0.022985 0.929072 -0.256641 0.870305 0.662289 -0.136141 0.565578" qvel="0.084667 0.035541 -0.027799 -0.137144 0.159981 -0.124574 -0.390751 -0.258129 -0.169813 0.128762 0.007767 0.118738 -0.050942 -0.215876 1.160160 0.495507 -1.246953 -0.915444 -2.329941 1.653218 -2.156871 -0.350735 -1.867003 -0.310990 0.988958 0.622725 -0.788417" /><key time="0.200" qpos="0.104373 0.006369 1.241773 0.978618 -0.027079 0.003500 -0.203867 0.238597 0.356035 -0.134052 0.181495 0.132742 -0.334168 0.043700 0.015311 -0.040919 -0.188268 -0.144364 -0.654590 -0.683067 -0.358779 0.038099 0.869146 -0.457691 0.880403 0.776385 0.010212 0.435941" qvel="0.116656 0.058033 -0.076402 -0.064470 -0.240038 0.686163 -2.068567 0.715370 -0.315438 -0.112133 0.766406 -0.616059 -0.038775 0.209183 1.077073 -0.011651 -0.983421 -0.140478 0.047413 -0.715830 0.083205 -0.427885 -2.680050 -0.013601 0.347815 2.157050 -0.186070" /><key time="0.225" qpos="0.119289 0.012087 1.238522 0.974606 -0.029592 0.012272 -0.221625 0.294559 0.372315 -0.130300 0.182296 0.120483 -0.363643 0.043462 0.005407 -0.087727 -0.199989 -0.109415 -0.667151 -0.638945 -0.367198 0.061901 0.856037 -0.605375 0.878315 0.753135 0.078113 0.497571" qvel="-0.009514 0.060861 0.095622 -0.157896 -0.099547 0.679971 -0.487223 -0.679346 0.438015 -0.145604 -0.092629 0.966034 0.018023 -0.196864 0.198496 0.107710 0.096469 1.144541 0.347449 -0.049172 0.320347 0.604642 -1.836389 -0.265224 -1.021902 -0.228118 -4.649936" /><key time="0.250" qpos="0.129565 0.016828 1.235515 0.971536 -0.037699 0.023031 -0.232737 0.318879 0.368885 -0.114020 0.182549 0.100813 -0.382865 0.043898 0.007515 -0.038126 -0.178087 -0.137914 -0.699726 -0.655723 -0.361063 0.067439 0.846266 -0.626268 0.882159 0.767483 0.127822 0.451421" qvel="0.093843 -0.023986 -0.007227 0.072982 0.178643 -1.539944 0.886294 0.085187 -0.221526 -0.076961 -0.196124 -0.311058 -0.086488 0.244878 1.522960 0.754293 -1.188972 -0.252995 -0.045743 0.084814 -0.351911 -0.373201 1.689631 0.582635 0.305540 0.313558 3.114145" /><key time="0.275" qpos="0.133814 0.020810 1.233356 0.970422 -0.039528 0.009340 -0.237973 0.273496 0.397372 -0.135813 0.182908 0.149722 -0.378539 0.043025 0.006056 -0.036845 -0.199439 -0.157857 -0.691169 -0.684527 -0.401623 0.056923 0.883061 -0.667557 0.848168 0.746424 0.113848 0.344490" qvel="0.103224 0.036336 -0.088901 -0.341591 0.197958 0.241188 -0.972793 0.250613 -0.028622 -0.053997 0.594780 -0.769468 -0.035441 0.271268 0.247493 -0.151584 -0.357219 -1.044497 -0.970840 0.082184 -0.192109 -0.144008 -0.847250 -0.083482 -0.375553 0.308779 0.589401" /><key time="0.300" qpos="0.141926 0.025630 1.230821 0.969137 -0.046552 0.024202 -0.240875 0.249657 0.368789 -0.134740 0.183400 0.174994 -0.381765 0.043599 0.006752 -0.047175 -0.197074 -0.185513 -0.692385 -0.700576 -0.422375 0.050930 0.785598 -0.652118 0.880913 0.809985 0.137657 0.317865" qvel="0.014817 0.016920 -0.015835 -0.132077 0.241307 -0.613655 -0.399148 -0.624460 -0.359447 0.075373 0.964486 0.323239 -0.024699 0.001979 -0.402303 -0.285017 -0.158964 0.275913 -0.766000 -0.508373 -1.675275 -1.013913 1.090252 -0.008168 0.068417 -0.380720 -0.693262" /><key time="0.325" qpos="0.146688 0.026949 1.232335 0.975127 -0.048584 0.021873 -0.215147 0.226342 0.374382 -0.114413 0.181382 0.148950 -0.369507 0.044023 -0.003560 -0.041464 -0.187605 -0.162627 -0.704636 -0.724026 -0.397727 0.023231 0.828648 -0.726988 0.872258 0.896036 0.120043 0.226866" qvel="0.057022 0.029120 0.044243 -0.328921 0.109874 -0.166034 0.074713 -0.489034 0.534319 -0.148667 -0.022673 0.433156 0.044510 -0.034191 0.235536 -0.422288 1.274671 0.437994 -0.123237 0.090551 -1.557574 -0.580346 0.662850 0.762898 0.900302 -0.543388 2.495709" /><key time="0.350" qpos="0.152491 0.029723 1.233529 0.971306 -0.056944 0.030217 -0.228928 0.269352 0.341603 -0.091150 0.178337 0.153421 -0.347757 0.043826 -0.013567 -0.062318 -0.164140 -0.195645 -0.673999 -0.696864 -0.402176 0.036023 0.847838 -0.640266 0.879167 0.893822 0.077081 0.255457" qvel="0.110190 -0.016650 0.001274 -0.023991 -0.293836 -0.199873 -0.105524 0.525714 0.354215 -0.267135 -0.329047 -0.131054 -0.011154 0.037742 1.367611 0.248403 -0.183899 0.491180 0.922722 -0.183957 0.492681 -0.060704 -0.131008 0.007836 0.946851 -1.841453 3.658603" /><key time="0.375" qpos="0.170926 0.028269 1.222278 0.972057 -0.061416 0.042208 -0.222603 0.304071 0.417325 -0.066362 0.167436 0.114427 -0.454536 0.054722 -0.001106 -0.041394 -0.161807 -0.142134 -0.767705 -0.640757 -0.378939 0.040654 0.872668 -0.686068 0.851829 1.029739 -0.050983 0.416917" qvel="0.071745 0.020928 -0.030399 -0.263522 0.095107 -0.204196 0.042452 -0.119296 -0.037990 0.265470 0.157426 -0.250434 -0.492571 -0.126847 0.206977 -0.209582 -0.395340 -0.109598 -0.285592 -0.159782 0.350862 -1.369752 0.838407 1.135970 0.191188 -1.044583 1.467121" /><key time="0.400" qpos="0.177190 0.027474 1.223742 0.976853 -0.064486 0.046926 -0.198489 0.278152 0.394769 -0.057640 0.183138 0.098294 -0.431687 0.043903 -0.016765 -0.043419 -0.171954 -0.136248 -0.749210 -0.648848 -0.379650 0.048076 0.823853 -0.688591 0.880575 0.984477 -0.089821 0.440546" qvel="0.022799 -0.070221 0.064484 0.172937 -0.530739 -0.054682 -0.607302 0.145673 -0.044100 -0.106612 0.423106 0.736119 0.006888 -0.240704 0.026295 -0.062306 -0.589121 2.060010 1.930864 -1.178844 1.096186 0.083973 -0.178904 -0.011779 -0.794912 -0.589912 1.516568" /><key time="0.425" qpos="0.187541 0.023932 1.220979 0.975200 -0.070175 0.029962 -0.207754 0.293914 0.440436 -0.051135 0.180850 0.123468 -0.425970 0.046131 -0.039231 -0.022299 -0.171660 -0.183626 -0.732067 -0.634923 -0.418457 0.112678 0.805594 -0.738840 0.879630 0.958374 -0.142960 0.599690" qvel="0.236248 -0.073076 -0.233601 0.095500 -1.433735 -2.233737 2.484788 3.724660 0.452979 -0.061139 -0.559797 -2.301350 -0.030254 -0.214952 1.872376 0.924957 -1.954538 -2.286718 0.367590 0.116630 3.379102 0.186875 -0.230510 -0.171585 0.459359 -1.155820 6.060133" /><key time="0.450" qpos="0.192152 0.026496 1.227091 0.971901 -0.097714 0.016730 -0.213498 0.279260 0.374897 0.012189 0.182032 0.168434 -0.298557 0.043465 -0.071457 -0.021210 -0.172616 -0.220560 -0.693122 -0.820305 -0.386080 0.021660 0.905472 -0.580162 0.834065 0.804342 -0.088560 0.556830" qvel="0.007554 0.008055 0.054502 0.059625 -0.898238 -0.192787 -1.587549 0.248238 -0.182470 -0.102736 0.960765 1.249383 -0.030294 -0.511458 1.505231 0.974020 -3.288545 1.088572 -0.933130 -0.318267 0.478322 -0.123586 2.115559 0.243620 -1.850084 0.409019 -3.028746" /><key time="0.475" qpos="0.215844 0.031261 1.220875 0.968514 -0.105151 -0.008791 -0.225492 0.273828 0.431972 0.008256 0.180827 0.233194 -0.265202 0.043654 -0.102464 -0.068866 -0.251543 -0.145986 -0.636287 -0.832375 -0.438750 0.094569 0.800826 -0.520305 0.880897 0.731923 -0.023369 0.445245" qvel="0.322888 0.000478 -0.148189 0.063843 -0.105652 0.084607 0.382786 1.232377 -0.152888 -0.037918 -0.021678 -1.069701 -0.001061 -0.103961 -0.171384 -0.776399 1.429502 -2.153755 -1.786663 0.764179 0.407379 0.567401 -1.257942 -0.038710 -0.581131 0.382435 -0.078825" /><key time="0.500" qpos="0.260061 0.035651 1.207095 0.975213 -0.118550 -0.006994 -0.186700 0.202501 0.482971 0.022852 0.181514 0.252814 -0.266051 0.043748 -0.148632 -0.084493 -0.275120 -0.147494 -0.641274 -0.862439 -0.491118 0.164385 0.844189 -0.761782 0.810066 0.808837 0.092058 0.429635" qvel="0.326502 0.067093 -0.071804 -0.470885 -0.391255 1.064332 -2.177851 0.120641 0.184826 -0.063187 0.635851 0.841304 0.007846 -0.239221 1.411255 -0.288904 0.012549 2.126715 1.177563 -1.514159 -0.645257 0.014605 -1.839388 -0.903439 0.769877 1.619592 -4.107893" /><key time="0.525" qpos="0.319646 0.039756 1.184700 0.968097 -0.149788 -0.006404 -0.200775 0.214798 0.529723 0.067110 0.182598 0.305952 -0.248548 0.043678 -0.206660 -0.080342 -0.280899 -0.177013 -0.697770 -1.021989 -0.457816 0.105937 0.751623 -0.997326 0.879695 0.776762 0.219982 0.511363" qvel="0.553669 0.019388 -0.192717 -0.617288 0.240646 0.066522 -0.127659 -0.097727 0.461059 0.002808 0.523679 0.365170 -0.041037 -0.585014 -0.244719 0.005951 0.152601 -0.792075 -2.009972 1.206795 -1.421288 -0.071392 -2.326142 -0.041298 0.006934 0.687418 0.761239" /><key time="0.550" qpos="0.399556 0.038180 1.155248 0.949998 -0.194378 0.004514 -0.244337 0.204840 0.535349 0.106501 0.182685 0.426120 -0.176273 0.044573 -0.272746 -0.057336 -0.318380 -0.215762 -0.785363 -1.308955 -0.169649 0.127253 0.650352 -1.190611 0.879940 0.654222 0.414473 0.787875" qvel="0.759802 -0.046214 -0.337444 -0.659328 -0.126742 -0.710487 0.151271 0.971854 0.159310 -0.052693 0.990508 -0.164203 -0.114243 -0.426066 -0.312390 -0.707014 -0.166603 -2.009320 -2.536431 4.596864 2.110287 -1.379038 -2.068077 0.044222 -1.279394 3.291295 2.894644" /><key time="0.575" qpos="0.507743 0.046041 1.101556 0.933373 -0.258571 0.011822 -0.248628 0.167715 0.534260 0.228951 0.182371 0.479201 0.005451 0.042697 -0.428182 -0.038432 -0.334631 -0.305495 -0.885258 -1.607933 0.922335 -0.165771 0.797306 -1.205524 0.838304 0.601686 0.840097 0.815282" qvel="0.989961 0.137793 -0.521749 -0.848806 -0.871225 -1.545407 1.550663 -0.137401 1.565290 -0.034579 0.043899 3.204173 0.057633 -1.853641 -1.152308 -0.719738 0.715038 1.230768 -2.504656 -1.728064 13.315988 -4.514908 0.730399 2.862786 -4.301245 4.010860 0.180343" /><key time="0.600" qpos="0.645747 0.073873 0.981459 0.836013 -0.324968 -0.103393 -0.429871 0.580930 0.552449 0.311013 0.157646 0.486069 0.395473 0.056098 -0.540501 0.545458 -0.498775 -0.444730 -0.643248 -1.696710 0.881443 0.115252 0.845528 -0.732634 0.866353 0.515868 1.070681 0.881589" qvel="1.431083 0.223421 -1.500059 -0.188535 0.053811 -4.036000 5.731157 0.665072 -1.533446 -0.421952 -1.066112 -0.579266 -0.282838 -2.024741 9.639915 -1.805358 1.334367 -2.818422 -2.005717 -0.039856 3.721576 -2.805247 6.181259 3.414345 4.081785 4.310091 -0.021437" /><key time="0.625" qpos="0.844824 0.101390 0.791448 0.751029 -0.384620 -0.111845 -0.524893 0.790944 0.543124 0.319136 -0.042129 0.418665 0.389638 -0.256108 -0.407146 0.859859 -0.494207 -0.411195 -0.496262 -1.832739 0.887928 0.102186 0.849437 -0.245361 0.881107 0.568317 1.054151 0.825945" qvel="2.075544 0.179247 -0.785140 -4.642310 -0.020454 5.177882 -0.930054 -1.149292 4.273195 -0.802445 -3.388881 -2.126131 1.663308 6.359551 -5.124128 1.149644 -0.008996 -2.537098 0.524049 -0.522430 11.278064 0.908142 -9.893148 -0.085439 0.534621 0.071988 -0.057763" /><key time="0.650" qpos="1.075712 0.126149 0.668181 0.632496 -0.602330 0.030868 -0.485999 0.818286 0.342968 0.628509 -0.043331 0.176263 0.246431 -0.691960 0.246610 0.812678 -0.536047 -0.417515 -0.273278 -1.751301 0.079996 0.870362 0.919461 -0.104676 0.879134 0.524477 1.064843 0.884663" qvel="1.923220 -0.038139 -1.015508 -1.977299 -1.621415 -2.650863 -0.627192 5.570947 -0.099470 -0.519563 4.356500 -5.325494 -8.388709 -27.446453 13.072745 0.544323 -4.958441 5.586670 3.560167 -6.917762 -1.343072 -0.435138 9.156518 0.311206 -6.780751 -0.098309 -0.417723" /><key time="0.675" qpos="1.330004 0.135676 0.520930 0.589757 -0.673218 0.098621 -0.435016 0.774143 0.534714 0.532097 0.010024 -0.236531 0.352833 0.092514 0.464912 0.153263 -0.340880 -0.458901 -0.108799 -0.839929 0.766993 0.966733 0.987426 -0.021548 0.880723 0.185579 0.665853 0.866847" qvel="2.229095 -0.013830 -1.655460 -3.195037 -0.015981 1.140591 -2.678402 0.132510 1.152736 -1.668330 -1.473329 -0.036772 -1.689990 -29.540089 -9.367425 3.564336 2.163901 8.835775 25.381832 -13.404368 8.575075 -2.066415 -1.819518 0.058354 -3.037830 -5.123644 -1.352549" /><key time="0.700" qpos="1.567020 0.136770 0.214266 0.460469 -0.749792 0.156353 -0.448703 0.828839 0.555087 0.375012 0.047924 -0.446176 0.234852 -0.049065 0.962994 0.873637 -0.182420 -0.404120 -0.198505 -0.747334 0.265632 0.798577 1.034169 0.100808 0.881534 0.141875 0.118762 0.881517" qvel="1.822759 -0.104508 -3.043304 -2.560297 1.051281 -1.306037 -0.295565 0.677599 -3.883233 -0.199444 -0.936451 -3.785163 -6.966579 9.957008 -8.146632 1.437220 4.610777 -1.347852 3.714935 -1.746471 -3.096343 0.668639 -0.276728 -0.031706 -6.819647 -0.841203 -0.002221" /><key time="0.725" qpos="1.604139 0.170073 0.143494 0.254308 -0.789098 0.107633 -0.548696 0.731461 0.380087 0.299294 -0.091619 -0.312370 0.400154 0.041123 0.173601 -0.715340 0.062459 -0.626681 0.023522 0.040383 0.917355 0.606183 1.055084 0.759996 0.854689 -0.374571 0.080808 0.690480" qvel="0.029875 0.413247 -0.599931 -1.455884 0.393127 -5.154646 -1.583591 -2.039200 -2.630442 -2.800322 3.586701 1.213653 -1.958289 -1.197039 24.808752 -2.989860 -5.266354 10.941086 18.034776 -2.078309 13.692633 0.051781 6.196856 -2.749322 -4.204984 -3.801393 -7.847733" /><key time="0.750" qpos="1.593505 0.208185 0.134272 0.178337 -0.785048 0.044561 -0.591532 0.781043 0.349398 0.284442 -0.329739 -0.343870 0.300160 -0.302815 -0.627186 0.706365 0.132641 -0.436939 -0.105936 0.026752 0.111210 0.890831 1.075206 1.033309 0.779849 -0.678234 -0.203824 0.764754" qvel="0.029452 0.333204 -0.088833 -1.198532 0.695268 1.647403 -0.359509 -4.401304 2.261341 -3.446233 -3.187518 6.768297 5.983611 13.602828 -13.492720 -0.755478 5.709186 2.872718 -0.861245 25.182341 -0.338722 -0.988596 -1.317987 4.934790 -1.900756 1.890139 -7.063031" /><key time="0.775" qpos="1.593976 0.182188 0.135189 0.234483 -0.770075 0.099320 -0.584926 0.794550 0.436606 0.264382 -0.459999 -0.675795 0.375877 -0.211297 -0.140065 0.891743 0.202608 -0.310012 -0.096478 0.104841 -0.348939 0.458627 1.054097 0.685525 0.910024 -1.379886 0.522937 0.886645" qvel="-0.084582 -0.260654 0.130790 1.372708 -0.243886 1.509905 -0.042602 2.218703 -0.413141 -5.254971 -6.411888 -1.370130 -17.338599 -21.030011 -5.994252 0.547658 -4.380043 -1.317298 -1.834659 -9.138715 29.203148 -0.007077 0.209193 -0.099702 -12.888943 0.504235 -0.487451" /><key time="0.800" qpos="1.600667 0.169629 0.134667 0.222795 -0.786803 0.062002 -0.572241 0.812717 0.537496 0.237389 -0.380672 -0.646326 0.388586 0.059996 0.779079 0.310853 0.181785 -0.340952 -0.028350 -0.010322 1.008475 -0.278933 0.848645 0.505884 0.881799 -1.490831 0.598213 0.633671" qvel="0.066024 0.145030 0.198500 -0.109600 -0.849081 -2.135667 -0.149882 0.058715 0.243590 1.575969 3.946300 -0.617934 -0.738868 -9.166840 0.236281 0.238576 -6.043565 4.146004 2.719200 -6.296830 13.100348 5.109549 -1.703282 -0.043043 -0.202827 -2.274839 2.721027" /><key time="0.825" qpos="1.606066 0.183435 0.133642 0.160084 -0.782604 0.060102 -0.598575 0.736500 0.390357 0.200832 -0.260862 -0.557848 0.303329 0.059795 -0.029554 0.241149 0.128736 -0.426642 0.184359 0.043966 0.697576 0.190313 0.778457 0.860653 0.879923 -1.359461 0.517922 0.701759" qvel="-0.054879 0.030868 -0.116259 -0.007547 0.607193 0.394829 0.492031 -2.653237 -0.453811 -2.520732 -1.376882 5.090975 0.663042 -9.879166 -2.445256 -2.670548 -2.830689 3.604415 0.061439 -3.714138 5.366652 -1.539305 3.157259 0.021856 -0.825501 1.950572 -5.561397" /><key time="0.850" qpos="1.602281 0.164170 0.131491 0.168499 -0.781465 0.042099 -0.599289 0.803250 0.362594 0.097688 -0.298316 -0.437637 0.463127 -0.117177 0.236149 0.348261 0.069198 -0.204072 0.217887 -0.220017 -0.434507 0.284022 1.062645 0.948544 0.856709 -1.405198 0.631552 -0.120776" qvel="-0.034106 -0.039766 -0.066338 0.155835 0.660442 0.261996 0.010134 -2.440609 -0.639553 -0.641988 4.909987 1.168603 -4.994507 1.234103 14.348408 0.406366 0.280432 -2.535681 -17.518975 -18.911229 -11.348924 -0.390720 -0.939485 -1.544028 7.082640 0.600125 -11.330186" /><key time="0.875" qpos="1.599402 0.117244 0.126128 0.109193 -0.777707 0.010805 -0.618976 0.730816 0.356905 -0.113049 -0.208838 -0.571775 0.265916 -0.114225 -0.205371 0.366237 0.063966 -0.123420 0.304107 0.045775 -0.173597 0.880593 1.055870 0.779366 0.815729 -1.522553 0.408309 0.903308" qvel="0.207817 0.111573 -0.881904 -4.086854 0.555577 3.575207 -2.753061 -10.753081 3.400967 -6.115361 -5.847612 8.230138 -7.902762 -10.121377 -32.085880 -0.721491 -2.314517 8.943665 -1.657273 3.716167 0.441054 4.752138 -6.066223 -8.289785 2.592003 4.222427 -10.101204" /><key time="0.900" qpos="1.603665 0.065653 0.126291 0.193598 -0.764902 0.114362 -0.603628 0.799233 0.480059 0.026071 -0.104373 -0.661795 0.370228 0.035446 -0.659782 0.237923 -0.067189 -0.423979 0.111946 -0.087704 0.295895 0.574601 0.832064 0.827362 0.890776 -1.186804 0.870065 0.711769" qvel="-0.093215 -0.484377 0.050333 1.309836 -0.419635 0.626523 1.422624 2.762141 -1.000514 3.170648 2.578170 -0.756833 -1.001084 -9.177567 -13.086262 -0.710978 -0.484212 0.598670 5.987560 8.309239 14.351369 -3.711294 0.290815 -0.566200 -7.872521 0.345462 0.248573" /><key time="0.925" qpos="1.615006 0.050026 0.122941 0.190140 -0.750041 0.129040 -0.620189 0.797853 0.434955 -0.138964 -0.339582 -0.950053 0.367926 -0.688208 0.341507 0.145536 -0.176449 -0.153240 -0.067410 -0.391720 -0.764118 0.184790 1.061836 0.461440 0.881664 -1.158295 0.460631 0.930561" qvel="0.160637 0.086003 -0.095571 -1.129490 0.707413 -0.523635 0.594549 -3.559098 0.667857 -8.680601 -2.837260 0.157794 -17.851176 -16.598188 -23.472421 -0.649258 6.985050 9.092216 20.040153 -16.551503 15.935357 -0.569735 -0.339857 -0.044263 -1.888999 -0.944765 -0.889485" /><key time="0.950" qpos="1.625224 0.049499 0.122318 0.166807 -0.742309 0.148040 -0.631852 0.708135 0.408212 -0.252734 -0.111896 -0.956753 0.392452 0.178616 0.045658 0.044564 -0.295684 -0.357737 -0.035785 0.057919 -0.623253 1.011403 0.542255 0.672276 0.642012 -1.492464 0.470765 0.935925" qvel="0.394859 0.186282 -0.198831 -2.423214 1.825900 -0.112400 0.414913 -7.280792 0.631666 -8.801993 -7.024864 10.709783 -2.528767 -28.969110 11.676275 -3.915444 8.357380 6.554783 -1.197862 -14.326358 -3.075160 -11.788221 1.967009 4.427819 -0.894912 0.850322 -1.823623" /><key time="0.975" qpos="1.627277 0.069761 0.117475 0.042399 -0.757141 0.075314 -0.647509 0.693178 0.249601 -0.224862 -0.116612 -1.088176 0.454017 0.051290 -0.000648 0.092945 -0.249079 -0.470047 0.080038 0.068937 0.258034 0.680559 1.152670 1.080206 0.452347 -1.448634 0.767058 0.746493" qvel="-0.081203 0.077644 0.232018 1.583747 -0.712692 -4.139563 3.566880 4.315095 -1.809983 4.511542 0.237079 -1.303749 -0.277869 3.143066 16.933107 0.566659 -5.574839 -6.238583 -3.511876 10.867950 15.590250 20.619049 -0.533373 0.155109 3.908864 -0.071198 11.395101" /><key time="1.000" qpos="1.632520 0.079392 0.130075 0.025231 -0.774705 -0.015068 -0.631639 0.805064 0.450777 -0.276150 -0.104501 -1.081288 0.398146 0.036911 -0.398962 -0.113699 -0.236354 -0.553028 -0.106390 0.044078 0.072218 0.681380 1.060525 1.059889 0.890511 -1.256700 0.485516 0.843086" qvel="0.014994 0.103058 -0.109472 0.971686 0.215298 0.357527 2.961907 -0.795285 1.531360 -12.434843 -1.321320 12.865304 -0.348666 -8.877520 -5.713684 0.406782 1.453141 1.672968 -0.151716 -14.100570 8.433794 -0.423899 0.012463 -0.836897 3.311004 0.294812 1.208100" /><key time="1.025" qpos="1.625174 0.065982 0.132004 0.037990 -0.780339 -0.028339 -0.623558 0.815275 0.561935 -0.353957 -0.009662 -0.927917 0.346187 0.071900 -0.235683 0.014107 -0.257452 -0.558677 -0.288684 0.080929 0.705004 0.880146 1.053700 0.985121 0.853774 -1.530922 0.758469 0.479076" qvel="0.042545 0.073193 0.018253 0.248093 0.237874 -0.388659 -0.665335 -0.022289 -1.306136 -0.554672 -1.097634 -0.460240 -1.056148 2.108518 -2.687509 0.442504 -3.343723 -2.701867 -2.273938 16.756034 0.135518 0.011787 -2.620333 -1.969060 1.651746 -1.578899 5.187986" /><key time="1.050" qpos="1.623570 0.060500 0.128201 0.075459 -0.776135 0.045997 -0.624343 0.796182 0.484766 -0.192153 -0.230650 -0.935582 0.365811 -0.060899 -1.001345 -0.076889 -0.226686 -0.516733 -0.223111 0.200886 0.452690 0.897232 0.720146 0.977507 0.912857 -1.514972 1.060392 0.632340" qvel="-0.079295 0.005914 -0.109842 -0.375860 -0.650453 0.875307 -0.494369 -0.227561 1.587364 -4.250087 -4.883687 -0.999027 -12.044517 -33.667714 -4.966011 1.192676 -6.091158 2.040979 4.667240 0.607316 -0.216697 1.022938 -1.139946 -0.788712 0.829964 0.863508 -2.602151" /><key time="1.075" qpos="1.633735 0.052602 0.130387 0.083750 -0.766546 0.049908 -0.634746 0.804637 0.531641 -0.341071 -0.093420 -1.084000 0.252190 -0.386579 0.628573 0.262666 -0.297016 -0.542692 -0.416221 0.094658 0.485675 0.834986 1.045499 0.762998 0.695252 -1.490419 0.799882 0.799813" qvel="0.111766 -0.119541 0.006016 -0.063519 0.411525 -0.158940 -0.437108 -0.258595 -2.204581 -0.104499 -1.641948 -2.218906 -11.512947 -9.496159 5.971498 -1.567755 -0.871610 0.574506 1.408608 -28.912690 7.770829 -0.685890 3.780041 -3.262038 0.116344 -4.763220 -0.233664" /><key time="1.100" qpos="1.657423 0.035591 0.119290 0.162932 -0.751318 0.125725 -0.627031 0.736959 0.404773 -0.282121 -0.255452 -1.098777 0.508916 0.135944 0.460358 0.404174 -0.264730 -0.667009 -0.378489 -0.216341 0.356783 0.464025 0.345306 0.859960 0.909217 -1.514842 0.477727 0.650328" qvel="0.187829 -0.162830 -0.172890 -0.188997 0.065349 0.576194 -0.221515 -1.880790 3.206723 -4.828194 -0.265479 -0.408048 -0.394571 23.846106 2.373781 2.594696 0.394002 1.926869 0.541577 44.356735 -30.297401 4.764752 -8.536769 -0.776173 -5.446378 0.322271 2.007722" /><key time="1.125" qpos="1.651165 0.018411 0.122091 0.223244 -0.732255 0.098929 -0.635750 0.783771 0.505358 -0.446946 0.186407 -1.080221 0.185967 0.043718 0.264238 0.400446 -0.265027 -0.795433 -0.428360 -0.335516 0.940176 0.261031 1.046189 0.013597 0.877608 -1.154283 0.299911 0.883417" qvel="-0.089423 -0.087264 0.088705 1.002750 0.086451 1.149190 -0.244521 0.561906 -0.024902 0.756930 0.026116 -1.213574 -0.654199 19.876746 -12.591309 -2.915521 4.626108 5.009389 4.335026 8.678156 21.602896 -2.341865 -0.695296 1.063562 6.925377 1.306305 -0.332352" /><key time="1.150" qpos="1.638672 -0.005844 0.138228 0.251834 -0.720974 0.098267 -0.638059 0.803123 0.552098 -0.404550 0.223538 -0.869607 0.376365 0.096675 0.482042 0.404463 -0.299657 -0.689745 -0.144405 0.105909 0.967178 0.498572 0.862129 0.290749 0.864610 -1.387495 0.366526 0.643784" qvel="0.117029 -0.697462 0.198308 -0.619970 3.575968 -0.706850 0.277485 -0.186704 -3.898898 0.952284 -5.501011 -2.459663 -2.736939 -7.816647 10.606409 2.570627 -2.400438 -5.938572 -0.599375 0.126375 17.325536 -5.505698 -0.636706 17.893750 -13.716686 -4.428498 5.197390" /><key time="1.175" qpos="1.647910 -0.001537 0.123600 0.202557 -0.744977 0.116267 -0.624869 0.785077 0.431692 -0.309746 -0.036118 -0.911165 0.194478 -0.506029 -0.252878 0.611653 -0.222953 -0.842418 -0.243347 -0.012988 -0.601186 0.911291 0.690297 0.712306 0.706803 -1.403665 0.523920 0.676698" qvel="0.256725 0.176428 -0.110481 -1.493342 1.109036 -0.563590 -0.172801 -5.169627 -1.006864 -5.750263 -2.810989 7.728442 8.993371 16.435889 -0.618389 -6.741009 1.889197 3.102651 -5.930390 5.544843 -1.405655 -3.817622 6.555705 1.114255 -1.793639 -0.087080 -5.893164" /><key time="1.200" qpos="1.656253 0.008538 0.112108 0.200708 -0.745876 0.078622 -0.630241 0.818456 0.423699 -0.438425 -0.181703 -0.994127 0.458023 -0.416678 -0.292520 0.408080 -0.323147 -0.595596 -0.361670 0.069702 0.028002 0.578926 1.052931 1.033806 0.876721 -1.314732 0.406312 0.571100" qvel="0.055370 0.039276 0.115177 -0.079340 -0.229937 -0.082236 1.005103 -2.397531 1.574453 -5.087023 2.645988 4.918844 -10.363986 -22.175510 -1.544818 -0.474014 -2.069465 4.945953 -0.916622 -29.027581 11.780226 -0.738657 -0.148036 0.224502 1.405838 0.888226 -14.099382" /><key time="1.225" qpos="1.659831 -0.011611 0.118451 0.232925 -0.744063 0.065410 -0.622766 0.789251 0.458846 -0.388290 -0.213233 -0.828428 0.384420 -0.738966 -0.142645 0.627251 -0.391230 -0.506440 -0.162207 0.052516 -0.366132 0.886453 0.750816 1.054887 0.650868 -1.000176 0.777396 0.369240" qvel="-0.079993 -0.257839 0.069057 0.948508 -0.431952 0.017658 -0.278752 2.714740 -1.425337 1.599282 -1.290259 -0.422033 7.140780 23.998817 7.285465 0.795144 -2.575849 -2.582236 -0.013373 2.343653 -1.221471 -6.365819 -0.303969 5.143391 -6.796334 -0.335569 2.983766" /></keyframe>
</mujoco>